Workbook

Sheet 배치결과
A1: 과목명 | B1: 병원명 | C1: T1 | D1: T2 | E1: T3 | F1: T4 | G1: T5 | H1: T6
A2: 서울부민 | B2: 5W | C2: A18 A23 A30 A31 | D2: A11 A17 A26 A29 A41 | E2: A08 A10 A15 A20 A25 | F2: B14 B18 B25 B30 B37 | G2: B11 B20 B24 B34 B38 | H2: B01 B21 B26 B31 B39
A3: 삼성서울 | B3: 15동 | F3: B09 B28 | G3: B08 B12
A4: 보라매 | B4: 82W | C4: A01 A08 | D4: A02 A27 | E4: A26 A32 | F4: B05 B22 | G4: B16 B26 | H4: B02 B12
A5: 보라매 | B5: 61W | C5: A07 A16 | D5: A03 A21 | E5: A19 A37 | F5: B15 B33 | G5: B27 B41 | H5: B04 B36
A6: 원주세브란스기독 | B6: 101W | C6: A09 A32 | D6: A01 A30 | E6: A05 A38 | F6: B19 B40 | G6: B32 B36 | H6: B06 B10
A7: 원주세브란스기독 | B7: 52W | C7: A15 A19 A37 A42 | D7: A12 A18 A34 A36 | E7: A28 A29 A33 A40 | F7: B24 B35 B39 | G7: B03 B21 B33 | H7: B15 B41
A8: 원주세브란스기독 | B8: 61W | C8: A02 A13 | D8: A06 A16 | E8: A14 A35 | F8: B02 B07 | G8: B01 B17 | H8: B13 B42
A9: 원주세브란스기독 | B9: 82W | C9: A03 A27 | D9: A04 A24 | E9: A22 A39 | F9: B16 B29 | G9: B05 B23 | H9: B20 B22
A10: 중앙보훈병원 | B10: 81W | C10: A12 A28 | D10: A33 A40 | E10: A34 A36 A42 | F10: B03 B06 | G10: B09 B10 B19 | H10: B28 B35
A11: 중앙보훈병원 | B11: 100W | C11: A10 A17 | D11: A22 A38 A39 | E11: A04 A31 | F11: B04 B13 B38 | G11: B31 B40 | H11: B25 B27
A12: 중앙보훈병원 | B12: 111W | C12: A14 A41 | D12: A13 A35 | E12: A07 A09 A21 | F12: B17 B23 | G12: B07 B14 | H12: B08 B37
A13: 중앙보훈병원 | B13: 121W | C13: A05 A06 | D13: A20 A23 A25 | E13: A11 A24 | F13: B11 B42 | G13: B18 B29 | H13: B30 B32 B34
H15: 최대 인원 충족

Sheet 명단
A1: A반
A2: 번호 | B2: 학번 | C2: 이름 | E2: 비고
A3: A01 | B3: 20241652 | C3: 고나영
A4: A02 | B4: 20241653 | C4: 곽나연
A5: A03 | B5: 20241654 | C5: 구서현
A6: A04 | B6: 20241655 | C6: 권소연
A7: A05 | B7: 20241656 | C7: 권예은
A8: A06 | B8: 20241657 | C8: 김나경
A9: A07 | B9: 20241658 | C9: 김단비
A10: A08 | B10: 20241659 | C10: 김단영
A11: A09 | B11: 20241662 | C11: 김민주
A12: A10 | B12: 20241663 | C12: 김서현
A13: A11 | B13: 20241664 | C13: 김성은
A14: A12 | B14: 20241665 | C14: 김세윤
... A38: A36 | B38: 20241719 | C38: 김지수
A39: A37 | B39: 20211773 | C39: 노부경 | E39: 복학예정자
A40: A38 | B40: 20221758 | C40: 백규민 | E40: 복학예정자
A41: A39 | B41: 20221759 | C41: 김재욱 | E41: 복학예정자
A42: A40 | B42: 20221760 | C42: 황재영 | E42: 복학예정자
A43: A41 | B43: 20221762 | C43: 최민영 | E43: 복학예정자
A44: A42 | B44: 20221763 | C44: 박준서 | E44: 복학예정자
A46: B반
A47: 번호 | B47: 학번 | C47: 이름 | E47: 비고
A48: B01 | B48: 20201917 | C48: 유민우
A49: B02 | B49: 20211775 | C49: 김진성
A50: B03 | B50: 20211781 | C50: 심병성
A51: B04 | B51: 20221764 | C51: 백진우
A52: B05 | B52: 20221770 | C52: 이두리
A53: B06 | B53: 20231714 | C53: 이가영
A54: B07 | B54: 20241666 | C54: 김예인
A55: B08 | B55: 20241668 | C55: 김은지
A56: B09 | B56: 20241669 | C56: 김주현
A57: B10 | B57: 20241674 | C57: 김희연
A58: B11 | B58: 20241677 | C58: 문채원
A59: B12 | B59: 20241679 | C59: 민세은
... A82: B35 | B82: 20251972 | C82: 김성진
A83: B36 | B83: 20221774 | C83: 문성식 | E83: 복학예정자
A84: B37 | B84: 20221775 | C84: 김우겸 | E84: 복학예정자
A85: B38 | B85: 20231675 | C85: 김옥수 | E85: 복학예정자
A86: B39 | B86: 20231688 | C86: 김윤하 | E86: 복학예정자
...

Sheet 배치결과_이름
A1: 과목명 | B1: 병원명 | C1: T1 | D1: T2 | E1: T3 | F1: T4 | G1: T5 | H1: T6
A2: 서울부민 | B2: 5W | C2: =IFERROR(VLOOKUP("A18",명단!A:C,3,FALSE),"A18")&" "&IFERROR(VLOOKUP("A23",명단!A:C,3,FALSE),"A23")&" "&IFERROR(VLOOKUP("A30",명단!A:C,3,FALSE),"A30")&" "&IFERROR(VLOOKUP("A31",명단!A:C,3,FALSE),"A31") -> 박수인 연제은 정연주 조민경 | D2: =IFERROR(VLOOKUP("A11",명단!A:C,3,FALSE),"A11")&" "&IFERROR(VLOOKUP("A17",명단!A:C,3,FALSE),"A17")&" "&IFERROR(VLOOKUP("A26",명단!A:C,3,FALSE),"A26")&" "&IFERROR(VLOOKUP("A29",명단!A:C,3,FALSE),"A29")&" "&IFERROR(VLOOKUP("A41",명단!A:C,3,FALSE),"A41") -> 김성은 민보나 이희서 점서원 최민영 | E2: =IFERROR(VLOOKUP("A08",명단!A:C,3,FALSE),"A08")&" "&IFERROR(VLOOKUP("A10",명단!A:C,3,FALSE),"A10")&" "&IFERROR(VLOOKUP("A15",명단!A:C,3,FALSE),"A15")&" "&IFERROR(VLOOKUP("A20",명단!A:C,3,FALSE),"A20")&" "&IFERROR(VLOOKUP("A25",명단!A:C,3,FALSE),"A25") -> 김단영 김서현 김현서 송예원 이민정 | F2: =IFERROR(VLOOKUP("B14",명단!A:C,3,FALSE),"B14")&" "&IFERROR(VLOOKUP("B18",명단!A:C,3,FALSE),"B18")&" "&IFERROR(VLOOKUP("B25",명단!A:C,3,FALSE),"B25")&" "&IFERROR(VLOOKUP("B30",명단!A:C,3,FALSE),"B30")&" "&IFERROR(VLOOKUP("B37",명단!A:C,3,FALSE),"B37") -> 안정민 이강희 정재경 이유진 김우겸 | G2: =IFERROR(VLOOKUP("B11",명단!A:C,3,FALSE),"B11")&" "&IFERROR(VLOOKUP("B20",명단!A:C,3,FALSE),"B20")&" "&IFERROR(VLOOKUP("B24",명단!A:C,3,FALSE),"B24")&" "&IFERROR(VLOOKUP("B34",명단!A:C,3,FALSE),"B34")&" "&IFERROR(VLOOKUP("B38",명단!A:C,3,FALSE),"B38") -> 문채원 이예은 신민준 임유진 김옥수 | H2: =IFERROR(VLOOKUP("B01",명단!A:C,3,FALSE),"B01")&" "&IFERROR(VLOOKUP("B21",명단!A:C,3,FALSE),"B21")&" "&IFERROR(VLOOKUP("B26",명단!A:C,3,FALSE),"B26")&" "&IFERROR(VLOOKUP("B31",명단!A:C,3,FALSE),"B31")&" "&IFERROR(VLOOKUP("B39",명단!A:C,3,FALSE),"B39") -> 유민우 주예진 김보미 위인애 김윤하
A3: 삼성서울 | B3: 15동 | F3: =IFERROR(VLOOKUP("B09",명단!A:C,3,FALSE),"B09")&" "&IFERROR(VLOOKUP("B28",명단!A:C,3,FALSE),"B28") -> 김주현 김하은 | G3: =IFERROR(VLOOKUP("B08",명단!A:C,3,FALSE),"B08")&" "&IFERROR(VLOOKUP("B12",명단!A:C,3,FALSE),"B12") -> 김은지 민세은
A4: 보라매 | B4: 82W | C4: =IFERROR(VLOOKUP("A01",명단!A:C,3,FALSE),"A01")&" "&IFERROR(VLOOKUP("A08",명단!A:C,3,FALSE),"A08") -> 고나영 김단영 | D4: =IFERROR(VLOOKUP("A02",명단!A:C,3,FALSE),"A02")&" "&IFERROR(VLOOKUP("A27",명단!A:C,3,FALSE),"A27") -> 곽나연 임혜린 | E4: =IFERROR(VLOOKUP("A26",명단!A:C,3,FALSE),"A26")&" "&IFERROR(VLOOKUP("A32",명단!A:C,3,FALSE),"A32") -> 이희서 조채은 | F4: =IFERROR(VLOOKUP("B05",명단!A:C,3,FALSE),"B05")&" "&IFERROR(VLOOKUP("B22",명단!A:C,3,FALSE),"B22") -> 이두리 최다연 | G4: =IFERROR(VLOOKUP("B16",명단!A:C,3,FALSE),"B16")&" "&IFERROR(VLOOKUP("B26",명단!A:C,3,FALSE),"B26") -> 유리 김보미 | H4: =IFERROR(VLOOKUP("B02",명단!A:C,3,FALSE),"B02")&" "&IFERROR(VLOOKUP("B12",명단!A:C,3,FALSE),"B12") -> 김진성 민세은
A5: 보라매 | B5: 61W | C5: =IFERROR(VLOOKUP("A07",명단!A:C,3,FALSE),"A07")&" "&IFERROR(VLOOKUP("A16",명단!A:C,3,FALSE),"A16") -> 김단비 류지호 | D5: =IFERROR(VLOOKUP("A03",명단!A:C,3,FALSE),"A03")&" "&IFERROR(VLOOKUP("A21",명단!A:C,3,FALSE),"A21") -> 구서현 송유나 | E5: =IFERROR(VLOOKUP("A19",명단!A:C,3,FALSE),"A19")&" "&IFERROR(VLOOKUP("A37",명단!A:C,3,FALSE),"A37") -> 손예지 노부경 | F5: =IFERROR(VLOOKUP("B15",명단!A:C,3,FALSE),"B15")&" "&IFERROR(VLOOKUP("B33",명단!A:C,3,FALSE),"B33") -> 양채은 방수영 | G5: =IFERROR(VLOOKUP("B27",명단!A:C,3,FALSE),"B27")&" "&IFERROR(VLOOKUP("B41",명단!A:C,3,FALSE),"B41") -> 하지혜 권세윤 | H5: =IFERROR(VLOOKUP("B04",명단!A:C,3,FALSE),"B04")&" "&IFERROR(VLOOKUP("B36",명단!A:C,3,FALSE),"B36") -> 백진우 문성식
A6: 원주세브란스기독 | B6: 101W | C6: =IFERROR(VLOOKUP("A09",명단!A:C,3,FALSE),"A09")&" "&IFERROR(VLOOKUP("A32",명단!A:C,3,FALSE),"A32") -> 김민주 조채은 | D6: =IFERROR(VLOOKUP("A01",명단!A:C,3,FALSE),"A01")&" "&IFERROR(VLOOKUP("A30",명단!A:C,3,FALSE),"A30") -> 고나영 정연주 | E6: =IFERROR(VLOOKUP("A05",명단!A:C,3,FALSE),"A05")&" "&IFERROR(VLOOKUP("A38",명단!A:C,3,FALSE),"A38") -> 권예은 백규민 | F6: =IFERROR(VLOOKUP("B19",명단!A:C,3,FALSE),"B19")&" "&IFERROR(VLOOKUP("B40",명단!A:C,3,FALSE),"B40") -> 이수안 김은비 | G6: =IFERROR(VLOOKUP("B32",명단!A:C,3,FALSE),"B32")&" "&IFERROR(VLOOKUP("B36",명단!A:C,3,FALSE),"B36") -> 권연우 문성식 | H6: =IFERROR(VLOOKUP("B06",명단!A:C,3,FALSE),"B06")&" "&IFERROR(VLOOKUP("B10",명단!A:C,3,FALSE),"B10") -> 이가영 김희연
A7: 원주세브란스기독 | B7: 52W | C7: =IFERROR(VLOOKUP("A15",명단!A:C,3,FALSE),"A15")&" "&IFERROR(VLOOKUP("A19",명단!A:C,3,FALSE),"A19")&" "&IFERROR(VLOOKUP("A37",명단!A:C,3,FALSE),"A37")&" "&IFERROR(VLOOKUP("A42",명단!A:C,3,FALSE),"A42") -> 김현서 손예지 노부경 박준서 | D7: =IFERROR(VLOOKUP("A12",명단!A:C,3,FALSE),"A12")&" "&IFERROR(VLOOKUP("A18",명단!A:C,3,FALSE),"A18")&" "&IFERROR(VLOOKUP("A34",명단!A:C,3,FALSE),"A34")&" "&IFERROR(VLOOKUP("A36",명단!A:C,3,FALSE),"A36") -> 김세윤 박수인 최정미 김지수 | E7: =IFERROR(VLOOKUP("A28",명단!A:C,3,FALSE),"A28")&" "&IFERROR(VLOOKUP("A29",명단!A:C,3,FALSE),"A29")&" "&IFERROR(VLOOKUP("A33",명단!A:C,3,FALSE),"A33")&" "&IFERROR(VLOOKUP("A40",명단!A:C,3,FALSE),"A40") -> 장해든 점서원 최은서 황재영 | F7: =IFERROR(VLOOKUP("B24",명단!A:C,3,FALSE),"B24")&" "&IFERROR(VLOOKUP("B35",명단!A:C,3,FALSE),"B35")&" "&IFERROR(VLOOKUP("B39",명단!A:C,3,FALSE),"B39") -> 신민준 김성진 김윤하 | G7: =IFERROR(VLOOKUP("B03",명단!A:C,3,FALSE),"B03")&" "&IFERROR(VLOOKUP("B21",명단!A:C,3,FALSE),"B21")&" "&IFERROR(VLOOKUP("B33",명단!A:C,3,FALSE),"B33") -> 심병성 주예진 방수영 | H7: =IFERROR(VLOOKUP("B15",명단!A:C,3,FALSE),"B15")&" "&IFERROR(VLOOKUP("B41",명단!A:C,3,FALSE),"B41") -> 양채은 권세윤
A8: 원주세브란스기독 | B8: 61W | C8: =IFERROR(VLOOKUP("A02",명단!A:C,3,FALSE),"A02")&" "&IFERROR(VLOOKUP("A13",명단!A:C,3,FALSE),"A13") -> 곽나연 김지수 | D8: =IFERROR(VLOOKUP("A06",명단!A:C,3,FALSE),"A06")&" "&IFERROR(VLOOKUP("A16",명단!A:C,3,FALSE),"A16") -> 김나경 류지호 | E8: =IFERROR(VLOOKUP("A14",명단!A:C,3,FALSE),"A14")&" "&IFERROR(VLOOKUP("A35",명단!A:C,3,FALSE),"A35") -> 김지연 최지은 | F8: =IFERROR(VLOOKUP("B02",명단!A:C,3,FALSE),"B02")&" "&IFERROR(VLOOKUP("B07",명단!A:C,3,FALSE),"B07") -> 김진성 김예인 | G8: =IFERROR(VLOOKUP("B01",명단!A:C,3,FALSE),"B01")&" "&IFERROR(VLOOKUP("B17",명단!A:C,3,FALSE),"B17") -> 유민우 윤지민 | H8: =IFERROR(VLOOKUP("B13",명단!A:C,3,FALSE),"B13")&" "&IFERROR(VLOOKUP("B42",명단!A:C,3,FALSE),"B42") -> 박승민 김성태
A9: 원주세브란스기독 | B9: 82W | C9: =IFERROR(VLOOKUP("A03",명단!A:C,3,FALSE),"A03")&" "&IFERROR(VLOOKUP("A27",명단!A:C,3,FALSE),"A27") -> 구서현 임혜린 | D9: =IFERROR(VLOOKUP("A04",명단!A:C,3,FALSE),"A04")&" "&IFERROR(VLOOKUP("A24",명단!A:C,3,FALSE),"A24") -> 권소연 이나영 | E9: =IFERROR(VLOOKUP("A22",명단!A:C,3,FALSE),"A22")&" "&IFERROR(VLOOKUP("A39",명단!A:C,3,FALSE),"A39") -> 안지수 김재욱 | F9: =IFERROR(VLOOKUP("B16",명단!A:C,3,FALSE),"B16")&" "&IFERROR(VLOOKUP("B29",명단!A:C,3,FALSE),"B29") -> 유리 박현정 | G9: =IFERROR(VLOOKUP("B05",명단!A:C,3,FALSE),"B05")&" "&IFERROR(VLOOKUP("B23",명단!A:C,3,FALSE),"B23") -> 이두리 김현진 | H9: =IFERROR(VLOOKUP("B20",명단!A:C,3,FALSE),"B20")&" "&IFERROR(VLOOKUP("B22",명단!A:C,3,FALSE),"B22") -> 이예은 최다연
A10: 중앙보훈병원 | B10: 81W | C10: =IFERROR(VLOOKUP("A12",명단!A:C,3,FALSE),"A12")&" "&IFERROR(VLOOKUP("A28",명단!A:C,3,FALSE),"A28") -> 김세윤 장해든 | D10: =IFERROR(VLOOKUP("A33",명단!A:C,3,FALSE),"A33")&" "&IFERROR(VLOOKUP("A40",명단!A:C,3,FALSE),"A40") -> 최은서 황재영 | E10: =IFERROR(VLOOKUP("A34",명단!A:C,3,FALSE),"A34")&" "&IFERROR(VLOOKUP("A36",명단!A:C,3,FALSE),"A36")&" "&IFERROR(VLOOKUP("A42",명단!A:C,3,FALSE),"A42") -> 최정미 김지수 박준서 | F10: =IFERROR(VLOOKUP("B03",명단!A:C,3,FALSE),"B03")&" "&IFERROR(VLOOKUP("B06",명단!A:C,3,FALSE),"B06") -> 심병성 이가영 | G10: =IFERROR(VLOOKUP("B09",명단!A:C,3,FALSE),"B09")&" "&IFERROR(VLOOKUP("B10",명단!A:C,3,FALSE),"B10")&" "&IFERROR(VLOOKUP("B19",명단!A:C,3,FALSE),"B19") -> 김주현 김희연 이수안 | H10: =IFERROR(VLOOKUP("B28",명단!A:C,3,FALSE),"B28")&" "&IFERROR(VLOOKUP("B35",명단!A:C,3,FALSE),"B35") -> 김하은 김성진
A11: 중앙보훈병원 | B11: 100W | C11: =IFERROR(VLOOKUP("A10",명단!A:C,3,FALSE),"A10")&" "&IFERROR(VLOOKUP("A17",명단!A:C,3,FALSE),"A17") -> 김서현 민보나 | D11: =IFERROR(VLOOKUP("A22",명단!A:C,3,FALSE),"A22")&" "&IFERROR(VLOOKUP("A38",명단!A:C,3,FALSE),"A38")&" "&IFERROR(VLOOKUP("A39",명단!A:C,3,FALSE),"A39") -> 안지수 백규민 김재욱 | E11: =IFERROR(VLOOKUP("A04",명단!A:C,3,FALSE),"A04")&" "&IFERROR(VLOOKUP("A31",명단!A:C,3,FALSE),"A31") -> 권소연 조민경 | F11: =IFERROR(VLOOKUP("B04",명단!A:C,3,FALSE),"B04")&" "&IFERROR(VLOOKUP("B13",명단!A:C,3,FALSE),"B13")&" "&IFERROR(VLOOKUP("B38",명단!A:C,3,FALSE),"B38") -> 백진우 박승민 김옥수 | G11: =IFERROR(VLOOKUP("B31",명단!A:C,3,FALSE),"B31")&" "&IFERROR(VLOOKUP("B40",명단!A:C,3,FALSE),"B40") -> 위인애 김은비 | H11: =IFERROR(VLOOKUP("B25",명단!A:C,3,FALSE),"B25")&" "&IFERROR(VLOOKUP("B27",명단!A:C,3,FALSE),"B27") -> 정재경 하지혜
A12: 중앙보훈병원 | B12: 111W | C12: =IFERROR(VLOOKUP("A14",명단!A:C,3,FALSE),"A14")&" "&IFERROR(VLOOKUP("A41",명단!A:C,3,FALSE),"A41") -> 김지연 최민영 | D12: =IFERROR(VLOOKUP("A13",명단!A:C,3,FALSE),"A13")&" "&IFERROR(VLOOKUP("A35",명단!A:C,3,FALSE),"A35") -> 김지수 최지은 | E12: =IFERROR(VLOOKUP("A07",명단!A:C,3,FALSE),"A07")&" "&IFERROR(VLOOKUP("A09",명단!A:C,3,FALSE),"A09")&" "&IFERROR(VLOOKUP("A21",명단!A:C,3,FALSE),"A21") -> 김단비 김민주 송유나 | F12: =IFERROR(VLOOKUP("B17",명단!A:C,3,FALSE),"B17")&" "&IFERROR(VLOOKUP("B23",명단!A:C,3,FALSE),"B23") -> 윤지민 김현진 | G12: =IFERROR(VLOOKUP("B07",명단!A:C,3,FALSE),"B07")&" "&IFERROR(VLOOKUP("B14",명단!A:C,3,FALSE),"B14") -> 김예인 안정민 | H12: =IFERROR(VLOOKUP("B08",명단!A:C,3,FALSE),"B08")&" "&IFERROR(VLOOKUP("B37",명단!A:C,3,FALSE),"B37") -> 김은지 김우겸
A13: 중앙보훈병원 | B13: 121W | C13: =IFERROR(VLOOKUP("A05",명단!A:C,3,FALSE),"A05")&" "&IFERROR(VLOOKUP("A06",명단!A:C,3,FALSE),"A06") -> 권예은 김나경 | D13: =IFERROR(VLOOKUP("A20",명단!A:C,3,FALSE),"A20")&" "&IFERROR(VLOOKUP("A23",명단!A:C,3,FALSE),"A23")&" "&IFERROR(VLOOKUP("A25",명단!A:C,3,FALSE),"A25") -> 송예원 연제은 이민정 | E13: =IFERROR(VLOOKUP("A11",명단!A:C,3,FALSE),"A11")&" "&IFERROR(VLOOKUP("A24",명단!A:C,3,FALSE),"A24") -> 김성은 이나영 | F13: =IFERROR(VLOOKUP("B11",명단!A:C,3,FALSE),"B11")&" "&IFERROR(VLOOKUP("B42",명단!A:C,3,FALSE),"B42") -> 문채원 김성태 | G13: =IFERROR(VLOOKUP("B18",명단!A:C,3,FALSE),"B18")&" "&IFERROR(VLOOKUP("B29",명단!A:C,3,FALSE),"B29") -> 이강희 박현정 | H13: =IFERROR(VLOOKUP("B30",명단!A:C,3,FALSE),"B30")&" "&IFERROR(VLOOKUP("B32",명단!A:C,3,FALSE),"B32")&" "&IFERROR(VLOOKUP("B34",명단!A:C,3,FALSE),"B34") -> 이유진 권연우 임유진

Sheet 학생별배치요약
A1: 기간 | D1: T1 | E1: T2 | F1: T3 | G1: T4 | H1: T5 | I1: T6
A2: 학생 ID | B2: 학생 학번 | C2: 학생 이름 | D2: T1 | E2: T2 | F2: T3 | G2: T4 | H2: T5 | I2: T6
A3: A01(내과1, 내과&외과1) | B3: 20241652 | C3: 고나영 | D3: 보라매(82W) | E3: 원주세브란스기독(101W)
A4: A02(내과1, 내과&외과1) | B4: 20241653 | C4: 곽나연 | D4: 원주세브란스기독(61W) | E4: 보라매(82W)
A5: A03(외과1, 내과&외과1) | B5: 20241654 | C5: 구서현 | D5: 원주세브란스기독(82W) | E5: 보라매(61W)
A6: A04(내과1, 내과&외과1) | B6: 20241655 | C6: 권소연 | E6: 원주세브란스기독(82W) | F6: 중앙보훈병원(100W)
A7: A05(내과1, 내과&외과1) | B7: 20241656 | C7: 권예은 | D7: 중앙보훈병원(121W) | F7: 원주세브란스기독(101W)
A8: A06(내과1, 내과&외과1) | B8: 20241657 | C8: 김나경 | D8: 중앙보훈병원(121W) | E8: 원주세브란스기독(61W)
A9: A07(내과1, 외과1) | B9: 20241658 | C9: 김단비 | D9: 보라매(61W) | F9: 중앙보훈병원(111W)
A10: A08(내과1, 외과1) | B10: 20241659 | C10: 김단영 | D10: 보라매(82W) | F10: 서울부민(5W)
A11: A09(내과1, 내과&외과1) | B11: 20241662 | C11: 김민주 | D11: 원주세브란스기독(101W) | F11: 중앙보훈병원(111W)
A12: A10(내과1, 외과1) | B12: 20241663 | C12: 김서현 | D12: 중앙보훈병원(100W) | F12: 서울부민(5W)
A13: A11(내과1, 외과1) | B13: 20241664 | C13: 김성은 | E13: 서울부민(5W) | F13: 중앙보훈병원(121W)
A14: A12(내과1, 외과1) | B14: 20241665 | C14: 김세윤 | D14: 중앙보훈병원(81W) | E14: 원주세브란스기독(52W)
A15: A13(내과1, 내과&외과1) | B15: 20241670 | C15: 김지수 | D15: 원주세브란스기독(61W) | E15: 중앙보훈병원(111W)
A16: A14(내과1, 내과&외과1) | B16: 20241671 | C16: 김지연 | D16: 중앙보훈병원(111W) | F16: 원주세브란스기독(61W)
A17: A15(내과1, 외과1) | B17: 20241672 | C17: 김현서 | D17: 원주세브란스기독(52W) | F17: 서울부민(5W)
A18: A16(외과1, 내과&외과1) | B18: 20241676 | C18: 류지호 | D18: 보라매(61W) | E18: 원주세브란스기독(61W)
A19: A17(내과1, 외과1) | B19: 20241678 | C19: 민보나 | D19: 중앙보훈병원(100W) | E19: 서울부민(5W)
A20: A18(내과1, 외과1) | B20: 20241680 | C20: 박수인 | D20: 서울부민(5W) | E20: 원주세브란스기독(52W)
A21: A19(내과1, 외과1) | B21: 20241682 | C21: 손예지 | D21: 원주세브란스기독(52W) | F21: 보라매(61W)
A22: A20(내과1, 외과1) | B22: 20241684 | C22: 송예원 | E22: 중앙보훈병원(121W) | F22: 서울부민(5W)
A23: A21(내과1, 외과1) | B23: 20241685 | C23: 송유나 | E23: 보라매(61W) | F23: 중앙보훈병원(111W)
A24: A22(내과1, 내과&외과1) | B24: 20241687 | C24: 안지수 | E24: 중앙보훈병원(100W) | F24: 원주세브란스기독(82W)
A25: A23(내과1, 외과1) | B25: 20241689 | C25: 연제은 | D25: 서울부민(5W) | E25: 중앙보훈병원(121W)
A26: A24(내과1, 내과&외과1) | B26: 20241693 | C26: 이나영 | E26: 원주세브란스기독(82W) | F26: 중앙보훈병원(121W)
A27: A25(내과1, 외과1) | B27: 20241694 | C27: 이민정 | E27: 중앙보훈병원(121W) | F27: 서울부민(5W)
A28: A26(내과1, 외과1) | B28: 20241699 | C28: 이희서 | E28: 서울부민(5W) | F28: 보라매(82W)
A29: A27(내과1, 내과&외과1) | B29: 20241700 | C29: 임혜린 | D29: 원주세브란스기독(82W) | E29: 보라매(82W)
A30: A28(내과1, 외과1) | B30: 20241701 | C30: 장해든 | D30: 중앙보훈병원(81W) | F30: 원주세브란스기독(52W)
A31: A29(내과1, 외과1) | B31: 20241702 | C31: 점서원 | E31: 서울부민(5W) | F31: 원주세브란스기독(52W)
A32: A30(외과1, 내과&외과1) | B32: 20241705 | C32: 정연주 | D32: 서울부민(5W) | E32: 원주세브란스기독(101W)
A33: A31(내과1, 외과1) | B33: 20241706 | C33: 조민경 | D33: 서울부민(5W) | F33: 중앙보훈병원(100W)
A34: A32(내과1, 내과&외과1) | B34: 20241707 | C34: 조채은 | D34: 원주세브란스기독(101W) | F34: 보라매(82W)
A35: A33(내과1, 외과1) | B35: 20241710 | C35: 최은서 | E35: 중앙보훈병원(81W) | F35: 원주세브란스기독(52W)
A36: A34(내과1, 외과1) | B36: 20241711 | C36: 최정미 | E36: 원주세브란스기독(52W) | F36: 중앙보훈병원(81W)
A37: A35(내과1, 내과&외과1) | B37: 20241712 | C37: 최지은 | E37: 중앙보훈병원(111W) | F37: 원주세브란스기독(61W)
A38: A36(내과1, 외과1) | B38: 20241719 | C38: 김지수 | E38: 원주세브란스기독(52W) | F38: 중앙보훈병원(81W)
A39: A37(내과1, 외과1) | B39: 20211773 | C39: 노부경 | D39: 원주세브란스기독(52W) | F39: 보라매(61W)
A40: A38(내과1, 내과&외과1) | B40: 20221758 | C40: 백규민 | E40: 중앙보훈병원(100W) | F40: 원주세브란스기독(101W)
...
